2023-12-08 16:55:44,371 INFO    MainThread:38830 [wandb_setup.py:_flush():76] Current SDK version is 0.16.1
2023-12-08 16:55:44,371 INFO    MainThread:38830 [wandb_setup.py:_flush():76] Configure stats pid to 38830
2023-12-08 16:55:44,371 INFO    MainThread:38830 [wandb_setup.py:_flush():76] Loading settings from /Users/silviaromanato/.config/wandb/settings
2023-12-08 16:55:44,371 INFO    MainThread:38830 [wandb_setup.py:_flush():76] Loading settings from /Users/silviaromanato/Desktop/EPFL/MA3/DeepLearning/biomed-team4/multimodal/wandb/settings
2023-12-08 16:55:44,371 INFO    MainThread:38830 [wandb_setup.py:_flush():76] Loading settings from environment variables: {'silent': 'true'}
2023-12-08 16:55:44,371 INFO    MainThread:38830 [wandb_setup.py:_flush():76] Applying setup settings: {'_disable_service': False}
2023-12-08 16:55:44,371 INFO    MainThread:38830 [wandb_setup.py:_flush():76] Inferring run settings from compute environment: {'program': '<python with no main file>'}
2023-12-08 16:55:44,371 WARNING MainThread:38830 [wandb_setup.py:_flush():76] interrupted
Traceback (most recent call last):
  File "/Users/silviaromanato/.conda/envs/lastenv/lib/python3.8/site-packages/IPython/core/interactiveshell.py", line 3505, in run_code
    exec(code_obj, self.user_global_ns, self.user_ns)
  File "/var/folders/kh/fr43342j0b998y80lvy2k2qh0000gn/T/ipykernel_38830/3361493712.py", line 1, in <module>
    grid_search(tabular=True,
  File "/Users/silviaromanato/Desktop/EPFL/MA3/DeepLearning/biomed-team4/multimodal/train.py", line 199, in grid_search
    run_name = build_group(tabular=tabular, vision=vision, tabular_params=tabular_params)
  File "/Users/silviaromanato/Desktop/EPFL/MA3/DeepLearning/biomed-team4/multimodal/train.py", line 69, in build_group
    wandb.init(group=run_name,
  File "/Users/silviaromanato/.conda/envs/lastenv/lib/python3.8/site-packages/wandb/sdk/wandb_init.py", line 1193, in init
    raise e
  File "/Users/silviaromanato/.conda/envs/lastenv/lib/python3.8/site-packages/wandb/sdk/wandb_init.py", line 1166, in init
    wi.setup(kwargs)
  File "/Users/silviaromanato/.conda/envs/lastenv/lib/python3.8/site-packages/wandb/sdk/wandb_init.py", line 322, in setup
    user_settings = self._wl._load_user_settings()
  File "/Users/silviaromanato/.conda/envs/lastenv/lib/python3.8/site-packages/wandb/sdk/wandb_setup.py", line 223, in _load_user_settings
    self._load_viewer(settings=settings)
  File "/Users/silviaromanato/.conda/envs/lastenv/lib/python3.8/site-packages/wandb/sdk/wandb_setup.py", line 216, in _load_viewer
    s.query_with_timeout()
  File "/Users/silviaromanato/.conda/envs/lastenv/lib/python3.8/site-packages/wandb/sdk/lib/server.py", line 35, in query_with_timeout
    viewer_tuple, viewer_thread = async_viewer()
  File "/Users/silviaromanato/.conda/envs/lastenv/lib/python3.8/site-packages/wandb/util.py", line 1188, in wrapper
    result = q.get(True, timeout)
  File "/Users/silviaromanato/.conda/envs/lastenv/lib/python3.8/queue.py", line 179, in get
    self.not_empty.wait(remaining)
  File "/Users/silviaromanato/.conda/envs/lastenv/lib/python3.8/threading.py", line 306, in wait
    gotit = waiter.acquire(True, timeout)
KeyboardInterrupt
2023-12-08 16:55:44,372 INFO    MainThread:38830 [wandb_init.py:_log_setup():524] Logging user logs to /Users/silviaromanato/Desktop/EPFL/MA3/DeepLearning/biomed-team4/multimodal/wandb/run-20231208_165544-cyg0mkbp/logs/debug.log
2023-12-08 16:55:44,372 INFO    MainThread:38830 [wandb_init.py:_log_setup():525] Logging internal logs to /Users/silviaromanato/Desktop/EPFL/MA3/DeepLearning/biomed-team4/multimodal/wandb/run-20231208_165544-cyg0mkbp/logs/debug-internal.log
2023-12-08 16:55:44,372 INFO    MainThread:38830 [wandb_init.py:_jupyter_setup():470] configuring jupyter hooks <wandb.sdk.wandb_init._WandbInit object at 0x7f7835c30280>
2023-12-08 16:55:44,372 INFO    MainThread:38830 [wandb_init.py:init():564] calling init triggers
2023-12-08 16:55:44,372 INFO    MainThread:38830 [wandb_init.py:init():571] wandb.init called with sweep_config: {}
config: {'tabular': True, 'vision': 'resnet50', 'tabular_params': {'dim_input': 87, 'hidden_dims': [256, 512], 'dropout_prob': 0.0, 'batch_norm': True}}
2023-12-08 16:55:44,372 INFO    MainThread:38830 [wandb_init.py:init():614] starting backend
2023-12-08 16:55:44,372 INFO    MainThread:38830 [wandb_init.py:init():618] setting up manager
2023-12-08 16:55:44,378 INFO    MainThread:38830 [backend.py:_multiprocessing_setup():105] multiprocessing start_methods=spawn,fork,forkserver, using: spawn
2023-12-08 16:55:44,380 INFO    MainThread:38830 [wandb_init.py:init():624] backend started and connected
2023-12-08 16:55:44,390 INFO    MainThread:38830 [wandb_run.py:_label_probe_notebook():1294] probe notebook
2023-12-08 16:55:44,390 INFO    MainThread:38830 [wandb_run.py:_label_probe_notebook():1304] Unable to probe notebook: 'NoneType' object has no attribute 'get'
2023-12-08 16:55:44,390 INFO    MainThread:38830 [wandb_init.py:init():716] updated telemetry
2023-12-08 16:55:44,537 INFO    MainThread:38830 [wandb_init.py:init():749] communicating run to backend with 90.0 second timeout
2023-12-08 16:55:45,066 ERROR   MainThread:38830 [wandb_init.py:init():775] encountered error: It appears that you do not have permission to access the requested resource. Please reach out to the project owner to grant you access. If you have the correct permissions, verify that there are no issues with your networking setup.(Error 404: Not Found)
2023-12-08 16:55:45,153 ERROR   MainThread:38830 [wandb_init.py:init():1188] It appears that you do not have permission to access the requested resource. Please reach out to the project owner to grant you access. If you have the correct permissions, verify that there are no issues with your networking setup.(Error 404: Not Found)
Traceback (most recent call last):
  File "/Users/silviaromanato/.conda/envs/lastenv/lib/python3.8/site-packages/wandb/sdk/wandb_init.py", line 1170, in init
    run = wi.init()
  File "/Users/silviaromanato/.conda/envs/lastenv/lib/python3.8/site-packages/wandb/sdk/wandb_init.py", line 781, in init
    raise error
wandb.errors.CommError: It appears that you do not have permission to access the requested resource. Please reach out to the project owner to grant you access. If you have the correct permissions, verify that there are no issues with your networking setup.(Error 404: Not Found)
2023-12-08 16:58:00,341 WARNING MsgRouterThr:38830 [router.py:message_loop():77] message_loop has been closed
